Workbook
Name DS_CongDoan: OFFSET('_DS'!$B$2,0,0,MAX(1,'_DS'!$H$2),1)
Name DS_VatLieu: OFFSET('_DS'!$D$2,0,0,MAX(1,'_DS'!$H$3),1)
Name DS_MaHang: OFFSET('_DS'!$F$2,0,0,MAX(1,'_DS'!$H$4),1)

Sheet HuongDan
A1: NAP | FILE TÍNH GIÁ GIA CÔNG CNC
A3: Mục tiêu | B3: Tính giá thành và giá bán dự kiến cho đơn hàng có nhiều công đoạn.
A4: Bước 1 | B4: đơn giá giờ máy, setup, chi phí chung, dự phòng và margin trong DonGia. theo máy móc
A5: Bước 2 | B5: Cập nhật giá vật liệu và tỷ lệ hao hụt trong VatLieu. hàng tháng
A6: Bước 3 | B6: Nhập mã hàng, số lượng, vật liệu, khối lượng phôi/cái trong TinhGia.
A7: Bước 4 | B7: Mỗi dòng ở CongDoan là một OP; mã hàng phải trùng TinhGia.
A8: Bước 5 | B8: Xem giá thành/cái, giá bán/cái và tổng giá bán tại TinhGia.
A9: Chú ý | B9: Nếu giờ máy đã gồm thợ vận hành, để nhân công riêng = 0 để tránh tính trùng.
A10: Công thức | B10: Giá bán = Giá thành / (1 - margin%). Các mức cài sẵn chỉ là tham khảo, cần thay theo dữ liệu NAP.
A11: Danh sách chọn | B11: Cột Công đoạn (CongDoan) lấy từ DonGia, cột Vật liệu (TinhGia) lấy từ VatLieu, cột Mã hàng (TinhGia) lấy từ CongDoan — tự cập nhật khi thêm/sửa. Ô tô đỏ = giá trị không còn trong danh sách gốc, cần chọn lại.

Sheet DonGia
A1: NAP | DANH MỤC ĐƠN GIÁ THAM KHẢO - CÓ THỂ SỬA
A3: Công đoạn | B3: Giờ máy (đ/h) | C3: Setup (đ/h) | D3: Nhân công riêng (đ/h) | E3: Ghi chú | G3: Tham số | H3: Giá trị | I3: Ghi chú
A4: Tiện CNC | B4: 280000 | C4: 180000 | D4: 0 | G4: Chi phí chung (%) | H4: 8 | I4: Chi phí vật tư tiêu hao
A5: Phay cơ | B5: 320000 | C5: 200000 | D5: 0 | G5: Dự phòng phế phẩm/làm lại (%) | H5: 4 | I5: Chi phí dự phòng
A6: Phay CNC 4 trục | B6: 460000 | C6: 250000 | D6: 0 | G6: Lợi nhuận trên doanh thu (%) | H6: 35
A7: Phay CNC 5 trục | B7: 1100000 | C7: 400000 | D7: 0
A8: Mài phẳng | B8: 250000 | C8: 150000 | D8: 0
A9: Mài tròn | B9: 300000 | C9: 180000 | D9: 0
A10: Cắt dây EDM | B10: 400000 | C10: 210000 | D10: 0 | E10: Tùy chiều cao, chiều dài, số lượt cắt
A11: Khoan CNC | B11: 150000 | C11: 110000 | D11: 0 | E11: Tùy vật liệu, số lỗ, độ sâu
A12: Taro CNC | B12: 180000 | C12: 120000 | D12: 0 | E12: Tùy vật liệu, số lỗ, độ sâu
A13: Khoan/taro máy cơ | B13: 120000 | C13: 60000 | D13: 0 | E13: Tùy vật liệu, số lỗ, độ sâu
A14: Cưa phôi | B14: 120000 | C14: 50000 | D14: 0 | E14: Tùy vật liệu
A15: Phá ba via/hoàn thiện | B15: 100000 | C15: 40000 | D15: 100000 | E15: Có thể tính nhân công riêng
A16: QC/đo kiểm | B16: 150000 | C16: 100000 | D16: 150000
A17: abnnnn
A18: Gia công ngoài | B18: 0 | C18: 0 | D18: 0 | E18: Nhập chi phí thực tế ở CongDoan

Sheet VatLieu
A1: NAP | DANH MỤC VẬT LIỆU THAM KHẢO
A3: Vật liệu | B3: Giá tham khảo (đ/kg) | C3: Hao hụt (%) | D3: Ghi chú
A4: SUS304 | B4: 80000 | C4: 10 | D4: Cập nhật báo giá NCC
A5: SUS316 | B5: 130000 | C5: 10
A6: Thép S45C | B6: 25000 | C6: 10
A7: SKD11 | B7: 280000 | C7: 10
A8: SKD61 | B8: 290000 | C8: 10
A9: Nhôm 6061 | B9: 180000 | C9: 12
A10: Đồng | B10: 360000 | C10: 15
A11: Nhựa POM | B11: 260000 | C11: 12
A12: Phíp cam | B12: 360000 | C12: 12
A13: Khác | B13: 0 | C13: 0 | D13: Nhập giá thực tế

Sheet CongDoan
A1: BẢNG NHẬP CÔNG ĐOẠN
A3: Mã hàng | B3: Mã-OP | C3: Công đoạn | D3: SL đơn hàng | E3: Setup (giờ) | F3: Chu kỳ (phút/cái) | G3: Giờ máy (đ/h) | H3: Setup (đ/h) | I3: Nhân công riêng (giờ/cái) | J3: Nhân công (đ/h) | K3: Dao cụ (đ/cái) | L3: Gia công ngoài (đ/cái) | M3: Tổng OP/lô (đ) | N3: OP/cái (đ)
A4: Bro1 | B4: 1 | C4: Phay CNC 3 trục | D4: 3 | E4: 1 | F4: 20 | G4: =IF(C4="","",IFERROR(VLOOKUP(C4,DonGia!$A$4:$D$203,2,FALSE),0)) -> 0 | H4: =IF(C4="","",IFERROR(VLOOKUP(C4,DonGia!$A$4:$D$203,3,FALSE),0)) -> 0 | J4: =IF(C4="","",IFERROR(VLOOKUP(C4,DonGia!$A$4:$D$203,4,FALSE),0)) -> 0 | M4: =IF(A4="","",E4*H4+D4*F4/60*G4+D4*I4*J4+D4*K4+D4*L4) -> 0 | N4: =IFERROR(M4/D4,0) -> 0
A5: Bro1 | B5: 2 | C5: Mài phẳng | D5: 3 | E5: 0.5 | F5: 10 | G5: =IF(C5="","",IFERROR(VLOOKUP(C5,DonGia!$A$4:$D$203,2,FALSE),0)) -> 250000 | H5: =IF(C5="","",IFERROR(VLOOKUP(C5,DonGia!$A$4:$D$203,3,FALSE),0)) -> 150000 | J5: =IF(C5="","",IFERROR(VLOOKUP(C5,DonGia!$A$4:$D$203,4,FALSE),0)) -> 0 | M5: =IF(A5="","",E5*H5+D5*F5/60*G5+D5*I5*J5+D5*K5+D5*L5) -> 200000 | N5: =IFERROR(M5/D5,0) -> 66666.667
A6: Bro1 | B6: 3 | C6: Gia công ngoài | D6: 3 | G6: =IF(C6="","",IFERROR(VLOOKUP(C6,DonGia!$A$4:$D$203,2,FALSE),0)) -> 0 | H6: =IF(C6="","",IFERROR(VLOOKUP(C6,DonGia!$A$4:$D$203,3,FALSE),0)) -> 0 | J6: =IF(C6="","",IFERROR(VLOOKUP(C6,DonGia!$A$4:$D$203,4,FALSE),0)) -> 0 | L6: 150000 | M6: =IF(A6="","",E6*H6+D6*F6/60*G6+D6*I6*J6+D6*K6+D6*L6) -> 450000 | N6: =IFERROR(M6/D6,0) -> 150000
D7: =IF(A7="","",IFERROR(VLOOKUP(A7,TinhGia!$A$4:$B$53,2,FALSE),0)) | G7: =IF(C7="","",IFERROR(VLOOKUP(C7,DonGia!$A$4:$D$203,2,FALSE),0)) | H7: =IF(C7="","",IFERROR(VLOOKUP(C7,DonGia!$A$4:$D$203,3,FALSE),0)) | J7: =IF(C7="","",IFERROR(VLOOKUP(C7,DonGia!$A$4:$D$203,4,FALSE),0)) | M7: =IF(A7="","",E7*H7+D7*F7/60*G7+D7*I7*J7+D7*K7+D7*L7) | N7: =IFERROR(M7/D7,0) -> 0
D8: =IF(A8="","",IFERROR(VLOOKUP(A8,TinhGia!$A$4:$B$53,2,FALSE),0)) | G8: =IF(C8="","",IFERROR(VLOOKUP(C8,DonGia!$A$4:$D$203,2,FALSE),0)) | H8: =IF(C8="","",IFERROR(VLOOKUP(C8,DonGia!$A$4:$D$203,3,FALSE),0)) | J8: =IF(C8="","",IFERROR(VLOOKUP(C8,DonGia!$A$4:$D$203,4,FALSE),0)) | M8: =IF(A8="","",E8*H8+D8*F8/60*G8+D8*I8*J8+D8*K8+D8*L8) | N8: =IFERROR(M8/D8,0) -> 0
D9: =IF(A9="","",IFERROR(VLOOKUP(A9,TinhGia!$A$4:$B$53,2,FALSE),0)) | G9: =IF(C9="","",IFERROR(VLOOKUP(C9,DonGia!$A$4:$D$203,2,FALSE),0)) | H9: =IF(C9="","",IFERROR(VLOOKUP(C9,DonGia!$A$4:$D$203,3,FALSE),0)) | J9: =IF(C9="","",IFERROR(VLOOKUP(C9,DonGia!$A$4:$D$203,4,FALSE),0)) | M9: =IF(A9="","",E9*H9+D9*F9/60*G9+D9*I9*J9+D9*K9+D9*L9) | N9: =IFERROR(M9/D9,0) -> 0
D10: =IF(A10="","",IFERROR(VLOOKUP(A10,TinhGia!$A$4:$B$53,2,FALSE),0)) | G10: =IF(C10="","",IFERROR(VLOOKUP(C10,DonGia!$A$4:$D$203,2,FALSE),0)) | H10: =IF(C10="","",IFERROR(VLOOKUP(C10,DonGia!$A$4:$D$203,3,FALSE),0)) | J10: =IF(C10="","",IFERROR(VLOOKUP(C10,DonGia!$A$4:$D$203,4,FALSE),0)) | M10: =IF(A10="","",E10*H10+D10*F10/60*G10+D10*I10*J10+D10*K10+D10*L10) | N10: =IFERROR(M10/D10,0) -> 0
D11: =IF(A11="","",IFERROR(VLOOKUP(A11,TinhGia!$A$4:$B$53,2,FALSE),0)) | G11: =IF(C11="","",IFERROR(VLOOKUP(C11,DonGia!$A$4:$D$203,2,FALSE),0)) | H11: =IF(C11="","",IFERROR(VLOOKUP(C11,DonGia!$A$4:$D$203,3,FALSE),0)) | J11: =IF(C11="","",IFERROR(VLOOKUP(C11,DonGia!$A$4:$D$203,4,FALSE),0)) | M11: =IF(A11="","",E11*H11+D11*F11/60*G11+D11*I11*J11+D11*K11+D11*L11) | N11: =IFERROR(M11/D11,0) -> 0
D12: =IF(A12="","",IFERROR(VLOOKUP(A12,TinhGia!$A$4:$B$53,2,FALSE),0)) | G12: =IF(C12="","",IFERROR(VLOOKUP(C12,DonGia!$A$4:$D$203,2,FALSE),0)) | H12: =IF(C12="","",IFERROR(VLOOKUP(C12,DonGia!$A$4:$D$203,3,FALSE),0)) | J12: =IF(C12="","",IFERROR(VLOOKUP(C12,DonGia!$A$4:$D$203,4,FALSE),0)) | M12: =IF(A12="","",E12*H12+D12*F12/60*G12+D12*I12*J12+D12*K12+D12*L12) | N12: =IFERROR(M12/D12,0) -> 0
D13: =IF(A13="","",IFERROR(VLOOKUP(A13,TinhGia!$A$4:$B$53,2,FALSE),0)) | G13: =IF(C13="","",IFERROR(VLOOKUP(C13,DonGia!$A$4:$D$203,2,FALSE),0)) | H13: =IF(C13="","",IFERROR(VLOOKUP(C13,DonGia!$A$4:$D$203,3,FALSE),0)) | J13: =IF(C13="","",IFERROR(VLOOKUP(C13,DonGia!$A$4:$D$203,4,FALSE),0)) | M13: =IF(A13="","",E13*H13+D13*F13/60*G13+D13*I13*J13+D13*K13+D13*L13) | N13: =IFERROR(M13/D13,0) -> 0
D14: =IF(A14="","",IFERROR(VLOOKUP(A14,TinhGia!$A$4:$B$53,2,FALSE),0)) | G14: =IF(C14="","",IFERROR(VLOOKUP(C14,DonGia!$A$4:$D$203,2,FALSE),0)) | H14: =IF(C14="","",IFERROR(VLOOKUP(C14,DonGia!$A$4:$D$203,3,FALSE),0)) | J14: =IF(C14="","",IFERROR(VLOOKUP(C14,DonGia!$A$4:$D$203,4,FALSE),0)) | M14: =IF(A14="","",E14*H14+D14*F14/60*G14+D14*I14*J14+D14*K14+D14*L14) | N14: =IFERROR(M14/D14,0) -> 0
D15: =IF(A15="","",IFERROR(VLOOKUP(A15,TinhGia!$A$4:$B$53,2,FALSE),0)) | G15: =IF(C15="","",IFERROR(VLOOKUP(C15,DonGia!$A$4:$D$203,2,FALSE),0)) | H15: =IF(C15="","",IFERROR(VLOOKUP(C15,DonGia!$A$4:$D$203,3,FALSE),0)) | J15: =IF(C15="","",IFERROR(VLOOKUP(C15,DonGia!$A$4:$D$203,4,FALSE),0)) | M15: =IF(A15="","",E15*H15+D15*F15/60*G15+D15*I15*J15+D15*K15+D15*L15) | N15: =IFERROR(M15/D15,0) -> 0
D16: =IF(A16="","",IFERROR(VLOOKUP(A16,TinhGia!$A$4:$B$53,2,FALSE),0)) | G16: =IF(C16="","",IFERROR(VLOOKUP(C16,DonGia!$A$4:$D$203,2,FALSE),0)) | H16: =IF(C16="","",IFERROR(VLOOKUP(C16,DonGia!$A$4:$D$203,3,FALSE),0)) | J16: =IF(C16="","",IFERROR(VLOOKUP(C16,DonGia!$A$4:$D$203,4,FALSE),0)) | M16: =IF(A16="","",E16*H16+D16*F16/60*G16+D16*I16*J16+D16*K16+D16*L16) | N16: =IFERROR(M16/D16,0) -> 0
D17: =IF(A17="","",IFERROR(VLOOKUP(A17,TinhGia!$A$4:$B$53,2,FALSE),0)) | G17: =IF(C17="","",IFERROR(VLOOKUP(C17,DonGia!$A$4:$D$203,2,FALSE),0)) | H17: =IF(C17="","",IFERROR(VLOOKUP(C17,DonGia!$A$4:$D$203,3,FALSE),0)) | J17: =IF(C17="","",IFERROR(VLOOKUP(C17,DonGia!$A$4:$D$203,4,FALSE),0)) | M17: =IF(A17="","",E17*H17+D17*F17/60*G17+D17*I17*J17+D17*K17+D17*L17) | N17: =IFERROR(M17/D17,0) -> 0
D18: =IF(A18="","",IFERROR(VLOOKUP(A18,TinhGia!$A$4:$B$53,2,FALSE),0)) | G18: =IF(C18="","",IFERROR(VLOOKUP(C18,DonGia!$A$4:$D$203,2,FALSE),0)) | H18: =IF(C18="","",IFERROR(VLOOKUP(C18,DonGia!$A$4:$D$203,3,FALSE),0)) | J18: =IF(C18="","",IFERROR(VLOOKUP(C18,DonGia!$A$4:$D$203,4,FALSE),0)) | M18: =IF(A18="","",E18*H18+D18*F18/60*G18+D18*I18*J18+D18*K18+D18*L18) | N18: =IFERROR(M18/D18,0) -> 0
... D199: =IF(A199="","",IFERROR(VLOOKUP(A199,TinhGia!$A$4:$B$53,2,FALSE),0)) | G199: =IF(C199="","",IFERROR(VLOOKUP(C199,DonGia!$A$4:$D$203,2,FALSE),0)) | H199: =IF(C199="","",IFERROR(VLOOKUP(C199,DonGia!$A$4:$D$203,3,FALSE),0)) | J199: =IF(C199="","",IFERROR(VLOOKUP(C199,DonGia!$A$4:$D$203,4,FALSE),0)) | M199: =IF(A199="","",E199*H199+D199*F199/60*G199+D199*I199*J199+D199*K199+D199*L199) | N199: =IFERROR(M199/D199,0) -> 0

Sheet TinhGia
A1: TÍNH GIÁ THÀNH TỰ ĐỘNG
A3: Mã hàng | B3: Số lượng | C3: Vật liệu | D3: Phôi (kg/cái) | E3: Giá vật liệu (đ/kg) | F3: Vật liệu/cái (đ) | G3: Chi phí GC | H3: Chi phí VC | I3: Ghi chú | J3: Trực tiếp/cái (đ) | K3: Chi phí chung/cái | L3: Dự phòng/cái | M3: Giá thành/cái | N3: Margin (%) | O3: Giá bán/cái (đ) | P3: Tổng giá bán (đ)
A4: Bro1 | B4: 3 | C4: SUS304 | D4: 1.2 | E4: =IF(C4="","",IFERROR(VLOOKUP(C4,VatLieu!$A$4:$B$203,2,FALSE),0)) -> 80000 | F4: =IF(A4="","",D4*E4*(1+IFERROR(VLOOKUP(C4,VatLieu!$A$4:$C$203,3,FALSE),0)/100)) -> 105600 | G4: =IF(A4="","",IFERROR(SUMIF(CongDoan!$A$4:$A$199,A4,CongDoan!$N$4:$N$199),0)) -> 216666.67 | H4: 0 | J4: =IF(A4="","",F4+G4+H4) -> 322266.67 | K4: =IF(A4="","",J4*DonGia!$H$4/100) -> 25781.333 | L4: =IF(A4="","",(J4+K4)*DonGia!$H$5/100) -> 13921.92 | M4: =IF(A4="","",J4+K4+L4) -> 361969.92 | N4: =DonGia!$H$6 -> 35 | O4: =IF(A4="","",IFERROR(M4/(1-N4/100),0)) -> 556876.8 | P4: =IF(A4="","",O4*B4) -> 1670630.4
E5: =IF(C5="","",IFERROR(VLOOKUP(C5,VatLieu!$A$4:$B$203,2,FALSE),0)) | F5: =IF(A5="","",D5*E5*(1+IFERROR(VLOOKUP(C5,VatLieu!$A$4:$C$203,3,FALSE),0)/100)) | G5: =IF(A5="","",IFERROR(SUMIF(CongDoan!$A$4:$A$199,A5,CongDoan!$N$4:$N$199),0)) | H5: 0 | J5: =IF(A5="","",F5+G5+H5) | K5: =IF(A5="","",J5*DonGia!$H$4/100) | L5: =IF(A5="","",(J5+K5)*DonGia!$H$5/100) | M5: =IF(A5="","",J5+K5+L5) | N5: =DonGia!$H$6 -> 35 | O5: =IF(A5="","",IFERROR(M5/(1-N5/100),0)) | P5: =IF(A5="","",O5*B5)
E6: =IF(C6="","",IFERROR(VLOOKUP(C6,VatLieu!$A$4:$B$203,2,FALSE),0)) | F6: =IF(A6="","",D6*E6*(1+IFERROR(VLOOKUP(C6,VatLieu!$A$4:$C$203,3,FALSE),0)/100)) | G6: =IF(A6="","",IFERROR(SUMIF(CongDoan!$A$4:$A$199,A6,CongDoan!$N$4:$N$199),0)) | H6: 0 | J6: =IF(A6="","",F6+G6+H6) | K6: =IF(A6="","",J6*DonGia!$H$4/100) | L6: =IF(A6="","",(J6+K6)*DonGia!$H$5/100) | M6: =IF(A6="","",J6+K6+L6) | N6: =DonGia!$H$6 -> 35 | O6: =IF(A6="","",IFERROR(M6/(1-N6/100),0)) | P6: =IF(A6="","",O6*B6)
E7: =IF(C7="","",IFERROR(VLOOKUP(C7,VatLieu!$A$4:$B$203,2,FALSE),0)) | F7: =IF(A7="","",D7*E7*(1+IFERROR(VLOOKUP(C7,VatLieu!$A$4:$C$203,3,FALSE),0)/100)) | G7: =IF(A7="","",IFERROR(SUMIF(CongDoan!$A$4:$A$199,A7,CongDoan!$N$4:$N$199),0)) | H7: 0 | J7: =IF(A7="","",F7+G7+H7) | K7: =IF(A7="","",J7*DonGia!$H$4/100) | L7: =IF(A7="","",(J7+K7)*DonGia!$H$5/100) | M7: =IF(A7="","",J7+K7+L7) | N7: =DonGia!$H$6 -> 35 | O7: =IF(A7="","",IFERROR(M7/(1-N7/100),0)) | P7: =IF(A7="","",O7*B7)
E8: =IF(C8="","",IFERROR(VLOOKUP(C8,VatLieu!$A$4:$B$203,2,FALSE),0)) | F8: =IF(A8="","",D8*E8*(1+IFERROR(VLOOKUP(C8,VatLieu!$A$4:$C$203,3,FALSE),0)/100)) | G8: =IF(A8="","",IFERROR(SUMIF(CongDoan!$A$4:$A$199,A8,CongDoan!$N$4:$N$199),0)) | H8: 0 | J8: =IF(A8="","",F8+G8+H8) | K8: =IF(A8="","",J8*DonGia!$H$4/100) | L8: =IF(A8="","",(J8+K8)*DonGia!$H$5/100) | M8: =IF(A8="","",J8+K8+L8) | N8: =DonGia!$H$6 -> 35 | O8: =IF(A8="","",IFERROR(M8/(1-N8/100),0)) | P8: =IF(A8="","",O8*B8)
E9: =IF(C9="","",IFERROR(VLOOKUP(C9,VatLieu!$A$4:$B$203,2,FALSE),0)) | F9: =IF(A9="","",D9*E9*(1+IFERROR(VLOOKUP(C9,VatLieu!$A$4:$C$203,3,FALSE),0)/100)) | G9: =IF(A9="","",IFERROR(SUMIF(CongDoan!$A$4:$A$199,A9,CongDoan!$N$4:$N$199),0)) | H9: 0 | J9: =IF(A9="","",F9+G9+H9) | K9: =IF(A9="","",J9*DonGia!$H$4/100) | L9: =IF(A9="","",(J9+K9)*DonGia!$H$5/100) | M9: =IF(A9="","",J9+K9+L9) | N9: =DonGia!$H$6 -> 35 | O9: =IF(A9="","",IFERROR(M9/(1-N9/100),0)) | P9: =IF(A9="","",O9*B9)
E10: =IF(C10="","",IFERROR(VLOOKUP(C10,VatLieu!$A$4:$B$203,2,FALSE),0)) | F10: =IF(A10="","",D10*E10*(1+IFERROR(VLOOKUP(C10,VatLieu!$A$4:$C$203,3,FALSE),0)/100)) | G10: =IF(A10="","",IFERROR(SUMIF(CongDoan!$A$4:$A$199,A10,CongDoan!$N$4:$N$199),0)) | H10: 0 | J10: =IF(A10="","",F10+G10+H10) | K10: =IF(A10="","",J10*DonGia!$H$4/100) | L10: =IF(A10="","",(J10+K10)*DonGia!$H$5/100) | M10: =IF(A10="","",J10+K10+L10) | N10: =DonGia!$H$6 -> 35 | O10: =IF(A10="","",IFERROR(M10/(1-N10/100),0)) | P10: =IF(A10="","",O10*B10)
E11: =IF(C11="","",IFERROR(VLOOKUP(C11,VatLieu!$A$4:$B$203,2,FALSE),0)) | F11: =IF(A11="","",D11*E11*(1+IFERROR(VLOOKUP(C11,VatLieu!$A$4:$C$203,3,FALSE),0)/100)) | G11: =IF(A11="","",IFERROR(SUMIF(CongDoan!$A$4:$A$199,A11,CongDoan!$N$4:$N$199),0)) | H11: 0 | J11: =IF(A11="","",F11+G11+H11) | K11: =IF(A11="","",J11*DonGia!$H$4/100) | L11: =IF(A11="","",(J11+K11)*DonGia!$H$5/100) | M11: =IF(A11="","",J11+K11+L11) | N11: =DonGia!$H$6 -> 35 | O11: =IF(A11="","",IFERROR(M11/(1-N11/100),0)) | P11: =IF(A11="","",O11*B11)
E12: =IF(C12="","",IFERROR(VLOOKUP(C12,VatLieu!$A$4:$B$203,2,FALSE),0)) | F12: =IF(A12="","",D12*E12*(1+IFERROR(VLOOKUP(C12,VatLieu!$A$4:$C$203,3,FALSE),0)/100)) | G12: =IF(A12="","",IFERROR(SUMIF(CongDoan!$A$4:$A$199,A12,CongDoan!$N$4:$N$199),0)) | H12: 0 | J12: =IF(A12="","",F12+G12+H12) | K12: =IF(A12="","",J12*DonGia!$H$4/100) | L12: =IF(A12="","",(J12+K12)*DonGia!$H$5/100) | M12: =IF(A12="","",J12+K12+L12) | N12: =DonGia!$H$6 -> 35 | O12: =IF(A12="","",IFERROR(M12/(1-N12/100),0)) | P12: =IF(A12="","",O12*B12)
E13: =IF(C13="","",IFERROR(VLOOKUP(C13,VatLieu!$A$4:$B$203,2,FALSE),0)) | F13: =IF(A13="","",D13*E13*(1+IFERROR(VLOOKUP(C13,VatLieu!$A$4:$C$203,3,FALSE),0)/100)) | G13: =IF(A13="","",IFERROR(SUMIF(CongDoan!$A$4:$A$199,A13,CongDoan!$N$4:$N$199),0)) | H13: 0 | J13: =IF(A13="","",F13+G13+H13) | K13: =IF(A13="","",J13*DonGia!$H$4/100) | L13: =IF(A13="","",(J13+K13)*DonGia!$H$5/100) | M13: =IF(A13="","",J13+K13+L13) | N13: =DonGia!$H$6 -> 35 | O13: =IF(A13="","",IFERROR(M13/(1-N13/100),0)) | P13: =IF(A13="","",O13*B13)
E14: =IF(C14="","",IFERROR(VLOOKUP(C14,VatLieu!$A$4:$B$203,2,FALSE),0)) | F14: =IF(A14="","",D14*E14*(1+IFERROR(VLOOKUP(C14,VatLieu!$A$4:$C$203,3,FALSE),0)/100)) | G14: =IF(A14="","",IFERROR(SUMIF(CongDoan!$A$4:$A$199,A14,CongDoan!$N$4:$N$199),0)) | H14: 0 | J14: =IF(A14="","",F14+G14+H14) | K14: =IF(A14="","",J14*DonGia!$H$4/100) | L14: =IF(A14="","",(J14+K14)*DonGia!$H$5/100) | M14: =IF(A14="","",J14+K14+L14) | N14: =DonGia!$H$6 -> 35 | O14: =IF(A14="","",IFERROR(M14/(1-N14/100),0)) | P14: =IF(A14="","",O14*B14)
E15: =IF(C15="","",IFERROR(VLOOKUP(C15,VatLieu!$A$4:$B$203,2,FALSE),0)) | F15: =IF(A15="","",D15*E15*(1+IFERROR(VLOOKUP(C15,VatLieu!$A$4:$C$203,3,FALSE),0)/100)) | G15: =IF(A15="","",IFERROR(SUMIF(CongDoan!$A$4:$A$199,A15,CongDoan!$N$4:$N$199),0)) | H15: 0 | J15: =IF(A15="","",F15+G15+H15) | K15: =IF(A15="","",J15*DonGia!$H$4/100) | L15: =IF(A15="","",(J15+K15)*DonGia!$H$5/100) | M15: =IF(A15="","",J15+K15+L15) | N15: =DonGia!$H$6 -> 35 | O15: =IF(A15="","",IFERROR(M15/(1-N15/100),0)) | P15: =IF(A15="","",O15*B15)
E16: =IF(C16="","",IFERROR(VLOOKUP(C16,VatLieu!$A$4:$B$203,2,FALSE),0)) | F16: =IF(A16="","",D16*E16*(1+IFERROR(VLOOKUP(C16,VatLieu!$A$4:$C$203,3,FALSE),0)/100)) | G16: =IF(A16="","",IFERROR(SUMIF(CongDoan!$A$4:$A$199,A16,CongDoan!$N$4:$N$199),0)) | H16: 0 | J16: =IF(A16="","",F16+G16+H16) | K16: =IF(A16="","",J16*DonGia!$H$4/100) | L16: =IF(A16="","",(J16+K16)*DonGia!$H$5/100) | M16: =IF(A16="","",J16+K16+L16) | N16: =DonGia!$H$6 -> 35 | O16: =IF(A16="","",IFERROR(M16/(1-N16/100),0)) | P16: =IF(A16="","",O16*B16)
... E53: =IF(C53="","",IFERROR(VLOOKUP(C53,VatLieu!$A$4:$B$203,2,FALSE),0)) | F53: =IF(A53="","",D53*E53*(1+IFERROR(VLOOKUP(C53,VatLieu!$A$4:$C$203,3,FALSE),0)/100)) | G53: =IF(A53="","",IFERROR(SUMIF(CongDoan!$A$4:$A$199,A53,CongDoan!$N$4:$N$199),0)) | H53: 0 | J53: =IF(A53="","",F53+G53+H53) | K53: =IF(A53="","",J53*DonGia!$H$4/100) | L53: =IF(A53="","",(J53+K53)*DonGia!$H$5/100) | M53: =IF(A53="","",J53+K53+L53) | N53: =DonGia!$H$6 -> 35 | O53: =IF(A53="","",IFERROR(M53/(1-N53/100),0)) | P53: =IF(A53="","",O53*B53)
A56: Ghi chú: | B56: Nhập cùng mã hàng ở TinhGia và CongDoan. Chi phí OP đã gồm setup nhập tại CongDoan; cột setup bổ sung chỉ dùng cho chi phí chưa nhập ở OP.

Sheet _DS
A1: stt_CD | B1: DS_CongDoan | C1: stt_VL | D1: DS_VatLieu | E1: stt_MH | F1: DS_MaHang | H1: Số lượng
A2: =IF(TRIM(INDEX(DonGia!$A:$A,4))="","",IF(COUNTIF(INDEX(DonGia!$A:$A,4):INDEX(DonGia!$A:$A,4),INDEX(DonGia!$A:$A,4))=1,MAX($A$1:A1)+1,"")) -> 1 | B2: =IFERROR(INDEX(DonGia!$A:$A,MATCH(ROW()-1,$A$2:$A$201,0)+3),"") -> Tiện CNC | C2: =IF(TRIM(INDEX(VatLieu!$A:$A,4))="","",IF(COUNTIF(INDEX(VatLieu!$A:$A,4):INDEX(VatLieu!$A:$A,4),INDEX(VatLieu!$A:$A,4))=1,MAX($C$1:C1)+1,"")) -> 1 | D2: =IFERROR(INDEX(VatLieu!$A:$A,MATCH(ROW()-1,$C$2:$C$201,0)+3),"") -> SUS304 | E2: =IF(TRIM(INDEX(CongDoan!$A:$A,4))="","",IF(COUNTIF(INDEX(CongDoan!$A:$A,4):INDEX(CongDoan!$A:$A,4),INDEX(CongDoan!$A:$A,4))=1,MAX($E$1:E1)+1,"")) -> 1 | F2: =IFERROR(INDEX(CongDoan!$A:$A,MATCH(ROW()-1,$E$2:$E$197,0)+3),"") -> Bro1 | H2: =MAX($A$2:$A$201) -> 15
A3: =IF(TRIM(INDEX(DonGia!$A:$A,5))="","",IF(COUNTIF(INDEX(DonGia!$A:$A,4):INDEX(DonGia!$A:$A,5),INDEX(DonGia!$A:$A,5))=1,MAX($A$1:A2)+1,"")) -> 2 | B3: =IFERROR(INDEX(DonGia!$A:$A,MATCH(ROW()-1,$A$2:$A$201,0)+3),"") -> Phay cơ | C3: =IF(TRIM(INDEX(VatLieu!$A:$A,5))="","",IF(COUNTIF(INDEX(VatLieu!$A:$A,4):INDEX(VatLieu!$A:$A,5),INDEX(VatLieu!$A:$A,5))=1,MAX($C$1:C2)+1,"")) -> 2 | D3: =IFERROR(INDEX(VatLieu!$A:$A,MATCH(ROW()-1,$C$2:$C$201,0)+3),"") -> SUS316 | E3: =IF(TRIM(INDEX(CongDoan!$A:$A,5))="","",IF(COUNTIF(INDEX(CongDoan!$A:$A,4):INDEX(CongDoan!$A:$A,5),INDEX(CongDoan!$A:$A,5))=1,MAX($E$1:E2)+1,"")) | F3: =IFERROR(INDEX(CongDoan!$A:$A,MATCH(ROW()-1,$E$2:$E$197,0)+3),"") | H3: =MAX($C$2:$C$201) -> 10
A4: =IF(TRIM(INDEX(DonGia!$A:$A,6))="","",IF(COUNTIF(INDEX(DonGia!$A:$A,4):INDEX(DonGia!$A:$A,6),INDEX(DonGia!$A:$A,6))=1,MAX($A$1:A3)+1,"")) -> 3 | B4: =IFERROR(INDEX(DonGia!$A:$A,MATCH(ROW()-1,$A$2:$A$201,0)+3),"") -> Phay CNC 4 trục | C4: =IF(TRIM(INDEX(VatLieu!$A:$A,6))="","",IF(COUNTIF(INDEX(VatLieu!$A:$A,4):INDEX(VatLieu!$A:$A,6),INDEX(VatLieu!$A:$A,6))=1,MAX($C$1:C3)+1,"")) -> 3 | D4: =IFERROR(INDEX(VatLieu!$A:$A,MATCH(ROW()-1,$C$2:$C$201,0)+3),"") -> Thép S45C | E4: =IF(TRIM(INDEX(CongDoan!$A:$A,6))="","",IF(COUNTIF(INDEX(CongDoan!$A:$A,4):INDEX(CongDoan!$A:$A,6),INDEX(CongDoan!$A:$A,6))=1,MAX($E$1:E3)+1,"")) | F4: =IFERROR(INDEX(CongDoan!$A:$A,MATCH(ROW()-1,$E$2:$E$197,0)+3),"") | H4: =MAX($E$2:$E$197) -> 1
A5: =IF(TRIM(INDEX(DonGia!$A:$A,7))="","",IF(COUNTIF(INDEX(DonGia!$A:$A,4):INDEX(DonGia!$A:$A,7),INDEX(DonGia!$A:$A,7))=1,MAX($A$1:A4)+1,"")) -> 4 | B5: =IFERROR(INDEX(DonGia!$A:$A,MATCH(ROW()-1,$A$2:$A$201,0)+3),"") -> Phay CNC 5 trục | C5: =IF(TRIM(INDEX(VatLieu!$A:$A,7))="","",IF(COUNTIF(INDEX(VatLieu!$A:$A,4):INDEX(VatLieu!$A:$A,7),INDEX(VatLieu!$A:$A,7))=1,MAX($C$1:C4)+1,"")) -> 4 | D5: =IFERROR(INDEX(VatLieu!$A:$A,MATCH(ROW()-1,$C$2:$C$201,0)+3),"") -> SKD11 | E5: =IF(TRIM(INDEX(CongDoan!$A:$A,7))="","",IF(COUNTIF(INDEX(CongDoan!$A:$A,4):INDEX(CongDoan!$A:$A,7),INDEX(CongDoan!$A:$A,7))=1,MAX($E$1:E4)+1,"")) | F5: =IFERROR(INDEX(CongDoan!$A:$A,MATCH(ROW()-1,$E$2:$E$197,0)+3),"")
A6: =IF(TRIM(INDEX(DonGia!$A:$A,8))="","",IF(COUNTIF(INDEX(DonGia!$A:$A,4):INDEX(DonGia!$A:$A,8),INDEX(DonGia!$A:$A,8))=1,MAX($A$1:A5)+1,"")) -> 5 | B6: =IFERROR(INDEX(DonGia!$A:$A,MATCH(ROW()-1,$A$2:$A$201,0)+3),"") -> Mài phẳng | C6: =IF(TRIM(INDEX(VatLieu!$A:$A,8))="","",IF(COUNTIF(INDEX(VatLieu!$A:$A,4):INDEX(VatLieu!$A:$A,8),INDEX(VatLieu!$A:$A,8))=1,MAX($C$1:C5)+1,"")) -> 5 | D6: =IFERROR(INDEX(VatLieu!$A:$A,MATCH(ROW()-1,$C$2:$C$201,0)+3),"") -> SKD61 | E6: =IF(TRIM(INDEX(CongDoan!$A:$A,8))="","",IF(COUNTIF(INDEX(CongDoan!$A:$A,4):INDEX(CongDoan!$A:$A,8),INDEX(CongDoan!$A:$A,8))=1,MAX($E$1:E5)+1,"")) | F6: =IFERROR(INDEX(CongDoan!$A:$A,MATCH(ROW()-1,$E$2:$E$197,0)+3),"")
A7: =IF(TRIM(INDEX(DonGia!$A:$A,9))="","",IF(COUNTIF(INDEX(DonGia!$A:$A,4):INDEX(DonGia!$A:$A,9),INDEX(DonGia!$A:$A,9))=1,MAX($A$1:A6)+1,"")) -> 6 | B7: =IFERROR(INDEX(DonGia!$A:$A,MATCH(ROW()-1,$A$2:$A$201,0)+3),"") -> Mài tròn | C7: =IF(TRIM(INDEX(VatLieu!$A:$A,9))="","",IF(COUNTIF(INDEX(VatLieu!$A:$A,4):INDEX(VatLieu!$A:$A,9),INDEX(VatLieu!$A:$A,9))=1,MAX($C$1:C6)+1,"")) -> 6 | D7: =IFERROR(INDEX(VatLieu!$A:$A,MATCH(ROW()-1,$C$2:$C$201,0)+3),"") -> Nhôm 6061 | E7: =IF(TRIM(INDEX(CongDoan!$A:$A,9))="","",IF(COUNTIF(INDEX(CongDoan!$A:$A,4):INDEX(CongDoan!$A:$A,9),INDEX(CongDoan!$A:$A,9))=1,MAX($E$1:E6)+1,"")) | F7: =IFERROR(INDEX(CongDoan!$A:$A,MATCH(ROW()-1,$E$2:$E$197,0)+3),"")
A8: =IF(TRIM(INDEX(DonGia!$A:$A,10))="","",IF(COUNTIF(INDEX(DonGia!$A:$A,4):INDEX(DonGia!$A:$A,10),INDEX(DonGia!$A:$A,10))=1,MAX($A$1:A7)+1,"")) -> 7 | B8: =IFERROR(INDEX(DonGia!$A:$A,MATCH(ROW()-1,$A$2:$A$201,0)+3),"") -> Cắt dây EDM | C8: =IF(TRIM(INDEX(VatLieu!$A:$A,10))="","",IF(COUNTIF(INDEX(VatLieu!$A:$A,4):INDEX(VatLieu!$A:$A,10),INDEX(VatLieu!$A:$A,10))=1,MAX($C$1:C7)+1,"")) -> 7 | D8: =IFERROR(INDEX(VatLieu!$A:$A,MATCH(ROW()-1,$C$2:$C$201,0)+3),"") -> Đồng | E8: =IF(TRIM(INDEX(CongDoan!$A:$A,10))="","",IF(COUNTIF(INDEX(CongDoan!$A:$A,4):INDEX(CongDoan!$A:$A,10),INDEX(CongDoan!$A:$A,10))=1,MAX($E$1:E7)+1,"")) | F8: =IFERROR(INDEX(CongDoan!$A:$A,MATCH(ROW()-1,$E$2:$E$197,0)+3),"")
A9: =IF(TRIM(INDEX(DonGia!$A:$A,11))="","",IF(COUNTIF(INDEX(DonGia!$A:$A,4):INDEX(DonGia!$A:$A,11),INDEX(DonGia!$A:$A,11))=1,MAX($A$1:A8)+1,"")) -> 8 | B9: =IFERROR(INDEX(DonGia!$A:$A,MATCH(ROW()-1,$A$2:$A$201,0)+3),"") -> Khoan CNC | C9: =IF(TRIM(INDEX(VatLieu!$A:$A,11))="","",IF(COUNTIF(INDEX(VatLieu!$A:$A,4):INDEX(VatLieu!$A:$A,11),INDEX(VatLieu!$A:$A,11))=1,MAX($C$1:C8)+1,"")) -> 8 | D9: =IFERROR(INDEX(VatLieu!$A:$A,MATCH(ROW()-1,$C$2:$C$201,0)+3),"") -> Nhựa POM | E9: =IF(TRIM(INDEX(CongDoan!$A:$A,11))="","",IF(COUNTIF(INDEX(CongDoan!$A:$A,4):INDEX(CongDoan!$A:$A,11),INDEX(CongDoan!$A:$A,11))=1,MAX($E$1:E8)+1,"")) | F9: =IFERROR(INDEX(CongDoan!$A:$A,MATCH(ROW()-1,$E$2:$E$197,0)+3),"")
A10: =IF(TRIM(INDEX(DonGia!$A:$A,12))="","",IF(COUNTIF(INDEX(DonGia!$A:$A,4):INDEX(DonGia!$A:$A,12),INDEX(DonGia!$A:$A,12))=1,MAX($A$1:A9)+1,"")) -> 9 | B10: =IFERROR(INDEX(DonGia!$A:$A,MATCH(ROW()-1,$A$2:$A$201,0)+3),"") -> Taro CNC | C10: =IF(TRIM(INDEX(VatLieu!$A:$A,12))="","",IF(COUNTIF(INDEX(VatLieu!$A:$A,4):INDEX(VatLieu!$A:$A,12),INDEX(VatLieu!$A:$A,12))=1,MAX($C$1:C9)+1,"")) -> 9 | D10: =IFERROR(INDEX(VatLieu!$A:$A,MATCH(ROW()-1,$C$2:$C$201,0)+3),"") -> Phíp cam | E10: =IF(TRIM(INDEX(CongDoan!$A:$A,12))="","",IF(COUNTIF(INDEX(CongDoan!$A:$A,4):INDEX(CongDoan!$A:$A,12),INDEX(CongDoan!$A:$A,12))=1,MAX($E$1:E9)+1,"")) | F10: =IFERROR(INDEX(CongDoan!$A:$A,MATCH(ROW()-1,$E$2:$E$197,0)+3),"")
A11: =IF(TRIM(INDEX(DonGia!$A:$A,13))="","",IF(COUNTIF(INDEX(DonGia!$A:$A,4):INDEX(DonGia!$A:$A,13),INDEX(DonGia!$A:$A,13))=1,MAX($A$1:A10)+1,"")) -> 10 | B11: =IFERROR(INDEX(DonGia!$A:$A,MATCH(ROW()-1,$A$2:$A$201,0)+3),"") -> Khoan/taro máy cơ | C11: =IF(TRIM(INDEX(VatLieu!$A:$A,13))="","",IF(COUNTIF(INDEX(VatLieu!$A:$A,4):INDEX(VatLieu!$A:$A,13),INDEX(VatLieu!$A:$A,13))=1,MAX($C$1:C10)+1,"")) -> 10 | D11: =IFERROR(INDEX(VatLieu!$A:$A,MATCH(ROW()-1,$C$2:$C$201,0)+3),"") -> Khác | E11: =IF(TRIM(INDEX(CongDoan!$A:$A,13))="","",IF(COUNTIF(INDEX(CongDoan!$A:$A,4):INDEX(CongDoan!$A:$A,13),INDEX(CongDoan!$A:$A,13))=1,MAX($E$1:E10)+1,"")) | F11: =IFERROR(INDEX(CongDoan!$A:$A,MATCH(ROW()-1,$E$2:$E$197,0)+3),"")
A12: =IF(TRIM(INDEX(DonGia!$A:$A,14))="","",IF(COUNTIF(INDEX(DonGia!$A:$A,4):INDEX(DonGia!$A:$A,14),INDEX(DonGia!$A:$A,14))=1,MAX($A$1:A11)+1,"")) -> 11 | B12: =IFERROR(INDEX(DonGia!$A:$A,MATCH(ROW()-1,$A$2:$A$201,0)+3),"") -> Cưa phôi | C12: =IF(TRIM(INDEX(VatLieu!$A:$A,14))="","",IF(COUNTIF(INDEX(VatLieu!$A:$A,4):INDEX(VatLieu!$A:$A,14),INDEX(VatLieu!$A:$A,14))=1,MAX($C$1:C11)+1,"")) | D12: =IFERROR(INDEX(VatLieu!$A:$A,MATCH(ROW()-1,$C$2:$C$201,0)+3),"") | E12: =IF(TRIM(INDEX(CongDoan!$A:$A,14))="","",IF(COUNTIF(INDEX(CongDoan!$A:$A,4):INDEX(CongDoan!$A:$A,14),INDEX(CongDoan!$A:$A,14))=1,MAX($E$1:E11)+1,"")) | F12: =IFERROR(INDEX(CongDoan!$A:$A,MATCH(ROW()-1,$E$2:$E$197,0)+3),"")
A13: =IF(TRIM(INDEX(DonGia!$A:$A,15))="","",IF(COUNTIF(INDEX(DonGia!$A:$A,4):INDEX(DonGia!$A:$A,15),INDEX(DonGia!$A:$A,15))=1,MAX($A$1:A12)+1,"")) -> 12 | B13: =IFERROR(INDEX(DonGia!$A:$A,MATCH(ROW()-1,$A$2:$A$201,0)+3),"") -> Phá ba via/hoàn thiện | C13: =IF(TRIM(INDEX(VatLieu!$A:$A,15))="","",IF(COUNTIF(INDEX(VatLieu!$A:$A,4):INDEX(VatLieu!$A:$A,15),INDEX(VatLieu!$A:$A,15))=1,MAX($C$1:C12)+1,"")) | D13: =IFERROR(INDEX(VatLieu!$A:$A,MATCH(ROW()-1,$C$2:$C$201,0)+3),"") | E13: =IF(TRIM(INDEX(CongDoan!$A:$A,15))="","",IF(COUNTIF(INDEX(CongDoan!$A:$A,4):INDEX(CongDoan!$A:$A,15),INDEX(CongDoan!$A:$A,15))=1,MAX($E$1:E12)+1,"")) | F13: =IFERROR(INDEX(CongDoan!$A:$A,MATCH(ROW()-1,$E$2:$E$197,0)+3),"")
A14: =IF(TRIM(INDEX(DonGia!$A:$A,16))="","",IF(COUNTIF(INDEX(DonGia!$A:$A,4):INDEX(DonGia!$A:$A,16),INDEX(DonGia!$A:$A,16))=1,MAX($A$1:A13)+1,"")) -> 13 | B14: =IFERROR(INDEX(DonGia!$A:$A,MATCH(ROW()-1,$A$2:$A$201,0)+3),"") -> QC/đo kiểm | C14: =IF(TRIM(INDEX(VatLieu!$A:$A,16))="","",IF(COUNTIF(INDEX(VatLieu!$A:$A,4):INDEX(VatLieu!$A:$A,16),INDEX(VatLieu!$A:$A,16))=1,MAX($C$1:C13)+1,"")) | D14: =IFERROR(INDEX(VatLieu!$A:$A,MATCH(ROW()-1,$C$2:$C$201,0)+3),"") | E14: =IF(TRIM(INDEX(CongDoan!$A:$A,16))="","",IF(COUNTIF(INDEX(CongDoan!$A:$A,4):INDEX(CongDoan!$A:$A,16),INDEX(CongDoan!$A:$A,16))=1,MAX($E$1:E13)+1,"")) | F14: =IFERROR(INDEX(CongDoan!$A:$A,MATCH(ROW()-1,$E$2:$E$197,0)+3),"")
A15: =IF(TRIM(INDEX(DonGia!$A:$A,17))="","",IF(COUNTIF(INDEX(DonGia!$A:$A,4):INDEX(DonGia!$A:$A,17),INDEX(DonGia!$A:$A,17))=1,MAX($A$1:A14)+1,"")) -> 14 | B15: =IFERROR(INDEX(DonGia!$A:$A,MATCH(ROW()-1,$A$2:$A$201,0)+3),"") -> abnnnn | C15: =IF(TRIM(INDEX(VatLieu!$A:$A,17))="","",IF(COUNTIF(INDEX(VatLieu!$A:$A,4):INDEX(VatLieu!$A:$A,17),INDEX(VatLieu!$A:$A,17))=1,MAX($C$1:C14)+1,"")) | D15: =IFERROR(INDEX(VatLieu!$A:$A,MATCH(ROW()-1,$C$2:$C$201,0)+3),"") | E15: =IF(TRIM(INDEX(CongDoan!$A:$A,17))="","",IF(COUNTIF(INDEX(CongDoan!$A:$A,4):INDEX(CongDoan!$A:$A,17),INDEX(CongDoan!$A:$A,17))=1,MAX($E$1:E14)+1,"")) | F15: =IFERROR(INDEX(CongDoan!$A:$A,MATCH(ROW()-1,$E$2:$E$197,0)+3),"")
A16: =IF(TRIM(INDEX(DonGia!$A:$A,18))="","",IF(COUNTIF(INDEX(DonGia!$A:$A,4):INDEX(DonGia!$A:$A,18),INDEX(DonGia!$A:$A,18))=1,MAX($A$1:A15)+1,"")) -> 15 | B16: =IFERROR(INDEX(DonGia!$A:$A,MATCH(ROW()-1,$A$2:$A$201,0)+3),"") -> Gia công ngoài | C16: =IF(TRIM(INDEX(VatLieu!$A:$A,18))="","",IF(COUNTIF(INDEX(VatLieu!$A:$A,4):INDEX(VatLieu!$A:$A,18),INDEX(VatLieu!$A:$A,18))=1,MAX($C$1:C15)+1,"")) | D16: =IFERROR(INDEX(VatLieu!$A:$A,MATCH(ROW()-1,$C$2:$C$201,0)+3),"") | E16: =IF(TRIM(INDEX(CongDoan!$A:$A,18))="","",IF(COUNTIF(INDEX(CongDoan!$A:$A,4):INDEX(CongDoan!$A:$A,18),INDEX(CongDoan!$A:$A,18))=1,MAX($E$1:E15)+1,"")) | F16: =IFERROR(INDEX(CongDoan!$A:$A,MATCH(ROW()-1,$E$2:$E$197,0)+3),"")
A17: =IF(TRIM(INDEX(DonGia!$A:$A,19))="","",IF(COUNTIF(INDEX(DonGia!$A:$A,4):INDEX(DonGia!$A:$A,19),INDEX(DonGia!$A:$A,19))=1,MAX($A$1:A16)+1,"")) | B17: =IFERROR(INDEX(DonGia!$A:$A,MATCH(ROW()-1,$A$2:$A$201,0)+3),"") | C17: =IF(TRIM(INDEX(VatLieu!$A:$A,19))="","",IF(COUNTIF(INDEX(VatLieu!$A:$A,4):INDEX(VatLieu!$A:$A,19),INDEX(VatLieu!$A:$A,19))=1,MAX($C$1:C16)+1,"")) | D17: =IFERROR(INDEX(VatLieu!$A:$A,MATCH(ROW()-1,$C$2:$C$201,0)+3),"") | E17: =IF(TRIM(INDEX(CongDoan!$A:$A,19))="","",IF(COUNTIF(INDEX(CongDoan!$A:$A,4):INDEX(CongDoan!$A:$A,19),INDEX(CongDoan!$A:$A,19))=1,MAX($E$1:E16)+1,"")) | F17: =IFERROR(INDEX(CongDoan!$A:$A,MATCH(ROW()-1,$E$2:$E$197,0)+3),"")
A18: =IF(TRIM(INDEX(DonGia!$A:$A,20))="","",IF(COUNTIF(INDEX(DonGia!$A:$A,4):INDEX(DonGia!$A:$A,20),INDEX(DonGia!$A:$A,20))=1,MAX($A$1:A17)+1,"")) | B18: =IFERROR(INDEX(DonGia!$A:$A,MATCH(ROW()-1,$A$2:$A$201,0)+3),"") | C18: =IF(TRIM(INDEX(VatLieu!$A:$A,20))="","",IF(COUNTIF(INDEX(VatLieu!$A:$A,4):INDEX(VatLieu!$A:$A,20),INDEX(VatLieu!$A:$A,20))=1,MAX($C$1:C17)+1,"")) | D18: =IFERROR(INDEX(VatLieu!$A:$A,MATCH(ROW()-1,$C$2:$C$201,0)+3),"") | E18: =IF(TRIM(INDEX(CongDoan!$A:$A,20))="","",IF(COUNTIF(INDEX(CongDoan!$A:$A,4):INDEX(CongDoan!$A:$A,20),INDEX(CongDoan!$A:$A,20))=1,MAX($E$1:E17)+1,"")) | F18: =IFERROR(INDEX(CongDoan!$A:$A,MATCH(ROW()-1,$E$2:$E$197,0)+3),"")
A19: =IF(TRIM(INDEX(DonGia!$A:$A,21))="","",IF(COUNTIF(INDEX(DonGia!$A:$A,4):INDEX(DonGia!$A:$A,21),INDEX(DonGia!$A:$A,21))=1,MAX($A$1:A18)+1,"")) | B19: =IFERROR(INDEX(DonGia!$A:$A,MATCH(ROW()-1,$A$2:$A$201,0)+3),"") | C19: =IF(TRIM(INDEX(VatLieu!$A:$A,21))="","",IF(COUNTIF(INDEX(VatLieu!$A:$A,4):INDEX(VatLieu!$A:$A,21),INDEX(VatLieu!$A:$A,21))=1,MAX($C$1:C18)+1,"")) | D19: =IFERROR(INDEX(VatLieu!$A:$A,MATCH(ROW()-1,$C$2:$C$201,0)+3),"") | E19: =IF(TRIM(INDEX(CongDoan!$A:$A,21))="","",IF(COUNTIF(INDEX(CongDoan!$A:$A,4):INDEX(CongDoan!$A:$A,21),INDEX(CongDoan!$A:$A,21))=1,MAX($E$1:E18)+1,"")) | F19: =IFERROR(INDEX(CongDoan!$A:$A,MATCH(ROW()-1,$E$2:$E$197,0)+3),"")
A20: =IF(TRIM(INDEX(DonGia!$A:$A,22))="","",IF(COUNTIF(INDEX(DonGia!$A:$A,4):INDEX(DonGia!$A:$A,22),INDEX(DonGia!$A:$A,22))=1,MAX($A$1:A19)+1,"")) | B20: =IFERROR(INDEX(DonGia!$A:$A,MATCH(ROW()-1,$A$2:$A$201,0)+3),"") | C20: =IF(TRIM(INDEX(VatLieu!$A:$A,22))="","",IF(COUNTIF(INDEX(VatLieu!$A:$A,4):INDEX(VatLieu!$A:$A,22),INDEX(VatLieu!$A:$A,22))=1,MAX($C$1:C19)+1,"")) | D20: =IFERROR(INDEX(VatLieu!$A:$A,MATCH(ROW()-1,$C$2:$C$201,0)+3),"") | E20: =IF(TRIM(INDEX(CongDoan!$A:$A,22))="","",IF(COUNTIF(INDEX(CongDoan!$A:$A,4):INDEX(CongDoan!$A:$A,22),INDEX(CongDoan!$A:$A,22))=1,MAX($E$1:E19)+1,"")) | F20: =IFERROR(INDEX(CongDoan!$A:$A,MATCH(ROW()-1,$E$2:$E$197,0)+3),"")
A21: =IF(TRIM(INDEX(DonGia!$A:$A,23))="","",IF(COUNTIF(INDEX(DonGia!$A:$A,4):INDEX(DonGia!$A:$A,23),INDEX(DonGia!$A:$A,23))=1,MAX($A$1:A20)+1,"")) | B21: =IFERROR(INDEX(DonGia!$A:$A,MATCH(ROW()-1,$A$2:$A$201,0)+3),"") | C21: =IF(TRIM(INDEX(VatLieu!$A:$A,23))="","",IF(COUNTIF(INDEX(VatLieu!$A:$A,4):INDEX(VatLieu!$A:$A,23),INDEX(VatLieu!$A:$A,23))=1,MAX($C$1:C20)+1,"")) | D21: =IFERROR(INDEX(VatLieu!$A:$A,MATCH(ROW()-1,$C$2:$C$201,0)+3),"") | E21: =IF(TRIM(INDEX(CongDoan!$A:$A,23))="","",IF(COUNTIF(INDEX(CongDoan!$A:$A,4):INDEX(CongDoan!$A:$A,23),INDEX(CongDoan!$A:$A,23))=1,MAX($E$1:E20)+1,"")) | F21: =IFERROR(INDEX(CongDoan!$A:$A,MATCH(ROW()-1,$E$2:$E$197,0)+3),"")
A22: =IF(TRIM(INDEX(DonGia!$A:$A,24))="","",IF(COUNTIF(INDEX(DonGia!$A:$A,4):INDEX(DonGia!$A:$A,24),INDEX(DonGia!$A:$A,24))=1,MAX($A$1:A21)+1,"")) | B22: =IFERROR(INDEX(DonGia!$A:$A,MATCH(ROW()-1,$A$2:$A$201,0)+3),"") | C22: =IF(TRIM(INDEX(VatLieu!$A:$A,24))="","",IF(COUNTIF(INDEX(VatLieu!$A:$A,4):INDEX(VatLieu!$A:$A,24),INDEX(VatLieu!$A:$A,24))=1,MAX($C$1:C21)+1,"")) | D22: =IFERROR(INDEX(VatLieu!$A:$A,MATCH(ROW()-1,$C$2:$C$201,0)+3),"") | E22: =IF(TRIM(INDEX(CongDoan!$A:$A,24))="","",IF(COUNTIF(INDEX(CongDoan!$A:$A,4):INDEX(CongDoan!$A:$A,24),INDEX(CongDoan!$A:$A,24))=1,MAX($E$1:E21)+1,"")) | F22: =IFERROR(INDEX(CongDoan!$A:$A,MATCH(ROW()-1,$E$2:$E$197,0)+3),"")
A23: =IF(TRIM(INDEX(DonGia!$A:$A,25))="","",IF(COUNTIF(INDEX(DonGia!$A:$A,4):INDEX(DonGia!$A:$A,25),INDEX(DonGia!$A:$A,25))=1,MAX($A$1:A22)+1,"")) | B23: =IFERROR(INDEX(DonGia!$A:$A,MATCH(ROW()-1,$A$2:$A$201,0)+3),"") | C23: =IF(TRIM(INDEX(VatLieu!$A:$A,25))="","",IF(COUNTIF(INDEX(VatLieu!$A:$A,4):INDEX(VatLieu!$A:$A,25),INDEX(VatLieu!$A:$A,25))=1,MAX($C$1:C22)+1,"")) | D23: =IFERROR(INDEX(VatLieu!$A:$A,MATCH(ROW()-1,$C$2:$C$201,0)+3),"") | E23: =IF(TRIM(INDEX(CongDoan!$A:$A,25))="","",IF(COUNTIF(INDEX(CongDoan!$A:$A,4):INDEX(CongDoan!$A:$A,25),INDEX(CongDoan!$A:$A,25))=1,MAX($E$1:E22)+1,"")) | F23: =IFERROR(INDEX(CongDoan!$A:$A,MATCH(ROW()-1,$E$2:$E$197,0)+3),"")
A24: =IF(TRIM(INDEX(DonGia!$A:$A,26))="","",IF(COUNTIF(INDEX(DonGia!$A:$A,4):INDEX(DonGia!$A:$A,26),INDEX(DonGia!$A:$A,26))=1,MAX($A$1:A23)+1,"")) | B24: =IFERROR(INDEX(DonGia!$A:$A,MATCH(ROW()-1,$A$2:$A$201,0)+3),"") | C24: =IF(TRIM(INDEX(VatLieu!$A:$A,26))="","",IF(COUNTIF(INDEX(VatLieu!$A:$A,4):INDEX(VatLieu!$A:$A,26),INDEX(VatLieu!$A:$A,26))=1,MAX($C$1:C23)+1,"")) | D24: =IFERROR(INDEX(VatLieu!$A:$A,MATCH(ROW()-1,$C$2:$C$201,0)+3),"") | E24: =IF(TRIM(INDEX(CongDoan!$A:$A,26))="","",IF(COUNTIF(INDEX(CongDoan!$A:$A,4):INDEX(CongDoan!$A:$A,26),INDEX(CongDoan!$A:$A,26))=1,MAX($E$1:E23)+1,"")) | F24: =IFERROR(INDEX(CongDoan!$A:$A,MATCH(ROW()-1,$E$2:$E$197,0)+3),"")
A25: =IF(TRIM(INDEX(DonGia!$A:$A,27))="","",IF(COUNTIF(INDEX(DonGia!$A:$A,4):INDEX(DonGia!$A:$A,27),INDEX(DonGia!$A:$A,27))=1,MAX($A$1:A24)+1,"")) | B25: =IFERROR(INDEX(DonGia!$A:$A,MATCH(ROW()-1,$A$2:$A$201,0)+3),"") | C25: =IF(TRIM(INDEX(VatLieu!$A:$A,27))="","",IF(COUNTIF(INDEX(VatLieu!$A:$A,4):INDEX(VatLieu!$A:$A,27),INDEX(VatLieu!$A:$A,27))=1,MAX($C$1:C24)+1,"")) | D25: =IFERROR(INDEX(VatLieu!$A:$A,MATCH(ROW()-1,$C$2:$C$201,0)+3),"") | E25: =IF(TRIM(INDEX(CongDoan!$A:$A,27))="","",IF(COUNTIF(INDEX(CongDoan!$A:$A,4):INDEX(CongDoan!$A:$A,27),INDEX(CongDoan!$A:$A,27))=1,MAX($E$1:E24)+1,"")) | F25: =IFERROR(INDEX(CongDoan!$A:$A,MATCH(ROW()-1,$E$2:$E$197,0)+3),"")
A26: =IF(TRIM(INDEX(DonGia!$A:$A,28))="","",IF(COUNTIF(INDEX(DonGia!$A:$A,4):INDEX(DonGia!$A:$A,28),INDEX(DonGia!$A:$A,28))=1,MAX($A$1:A25)+1,"")) | B26: =IFERROR(INDEX(DonGia!$A:$A,MATCH(ROW()-1,$A$2:$A$201,0)+3),"") | C26: =IF(TRIM(INDEX(VatLieu!$A:$A,28))="","",IF(COUNTIF(INDEX(VatLieu!$A:$A,4):INDEX(VatLieu!$A:$A,28),INDEX(VatLieu!$A:$A,28))=1,MAX($C$1:C25)+1,"")) | D26: =IFERROR(INDEX(VatLieu!$A:$A,MATCH(ROW()-1,$C$2:$C$201,0)+3),"") | E26: =IF(TRIM(INDEX(CongDoan!$A:$A,28))="","",IF(COUNTIF(INDEX(CongDoan!$A:$A,4):INDEX(CongDoan!$A:$A,28),INDEX(CongDoan!$A:$A,28))=1,MAX($E$1:E25)+1,"")) | F26: =IFERROR(INDEX(CongDoan!$A:$A,MATCH(ROW()-1,$E$2:$E$197,0)+3),"")
A27: =IF(TRIM(INDEX(DonGia!$A:$A,29))="","",IF(COUNTIF(INDEX(DonGia!$A:$A,4):INDEX(DonGia!$A:$A,29),INDEX(DonGia!$A:$A,29))=1,MAX($A$1:A26)+1,"")) | B27: =IFERROR(INDEX(DonGia!$A:$A,MATCH(ROW()-1,$A$2:$A$201,0)+3),"") | C27: =IF(TRIM(INDEX(VatLieu!$A:$A,29))="","",IF(COUNTIF(INDEX(VatLieu!$A:$A,4):INDEX(VatLieu!$A:$A,29),INDEX(VatLieu!$A:$A,29))=1,MAX($C$1:C26)+1,"")) | D27: =IFERROR(INDEX(VatLieu!$A:$A,MATCH(ROW()-1,$C$2:$C$201,0)+3),"") | E27: =IF(TRIM(INDEX(CongDoan!$A:$A,29))="","",IF(COUNTIF(INDEX(CongDoan!$A:$A,4):INDEX(CongDoan!$A:$A,29),INDEX(CongDoan!$A:$A,29))=1,MAX($E$1:E26)+1,"")) | F27: =IFERROR(INDEX(CongDoan!$A:$A,MATCH(ROW()-1,$E$2:$E$197,0)+3),"")
A28: =IF(TRIM(INDEX(DonGia!$A:$A,30))="","",IF(COUNTIF(INDEX(DonGia!$A:$A,4):INDEX(DonGia!$A:$A,30),INDEX(DonGia!$A:$A,30))=1,MAX($A$1:A27)+1,"")) | B28: =IFERROR(INDEX(DonGia!$A:$A,MATCH(ROW()-1,$A$2:$A$201,0)+3),"") | C28: =IF(TRIM(INDEX(VatLieu!$A:$A,30))="","",IF(COUNTIF(INDEX(VatLieu!$A:$A,4):INDEX(VatLieu!$A:$A,30),INDEX(VatLieu!$A:$A,30))=1,MAX($C$1:C27)+1,"")) | D28: =IFERROR(INDEX(VatLieu!$A:$A,MATCH(ROW()-1,$C$2:$C$201,0)+3),"") | E28: =IF(TRIM(INDEX(CongDoan!$A:$A,30))="","",IF(COUNTIF(INDEX(CongDoan!$A:$A,4):INDEX(CongDoan!$A:$A,30),INDEX(CongDoan!$A:$A,30))=1,MAX($E$1:E27)+1,"")) | F28: =IFERROR(INDEX(CongDoan!$A:$A,MATCH(ROW()-1,$E$2:$E$197,0)+3),"")
A29: =IF(TRIM(INDEX(DonGia!$A:$A,31))="","",IF(COUNTIF(INDEX(DonGia!$A:$A,4):INDEX(DonGia!$A:$A,31),INDEX(DonGia!$A:$A,31))=1,MAX($A$1:A28)+1,"")) | B29: =IFERROR(INDEX(DonGia!$A:$A,MATCH(ROW()-1,$A$2:$A$201,0)+3),"") | C29: =IF(TRIM(INDEX(VatLieu!$A:$A,31))="","",IF(COUNTIF(INDEX(VatLieu!$A:$A,4):INDEX(VatLieu!$A:$A,31),INDEX(VatLieu!$A:$A,31))=1,MAX($C$1:C28)+1,"")) | D29: =IFERROR(INDEX(VatLieu!$A:$A,MATCH(ROW()-1,$C$2:$C$201,0)+3),"") | E29: =IF(TRIM(INDEX(CongDoan!$A:$A,31))="","",IF(COUNTIF(INDEX(CongDoan!$A:$A,4):INDEX(CongDoan!$A:$A,31),INDEX(CongDoan!$A:$A,31))=1,MAX($E$1:E28)+1,"")) | F29: =IFERROR(INDEX(CongDoan!$A:$A,MATCH(ROW()-1,$E$2:$E$197,0)+3),"")
A30: =IF(TRIM(INDEX(DonGia!$A:$A,32))="","",IF(COUNTIF(INDEX(DonGia!$A:$A,4):INDEX(DonGia!$A:$A,32),INDEX(DonGia!$A:$A,32))=1,MAX($A$1:A29)+1,"")) | B30: =IFERROR(INDEX(DonGia!$A:$A,MATCH(ROW()-1,$A$2:$A$201,0)+3),"") | C30: =IF(TRIM(INDEX(VatLieu!$A:$A,32))="","",IF(COUNTIF(INDEX(VatLieu!$A:$A,4):INDEX(VatLieu!$A:$A,32),INDEX(VatLieu!$A:$A,32))=1,MAX($C$1:C29)+1,"")) | D30: =IFERROR(INDEX(VatLieu!$A:$A,MATCH(ROW()-1,$C$2:$C$201,0)+3),"") | E30: =IF(TRIM(INDEX(CongDoan!$A:$A,32))="","",IF(COUNTIF(INDEX(CongDoan!$A:$A,4):INDEX(CongDoan!$A:$A,32),INDEX(CongDoan!$A:$A,32))=1,MAX($E$1:E29)+1,"")) | F30: =IFERROR(INDEX(CongDoan!$A:$A,MATCH(ROW()-1,$E$2:$E$197,0)+3),"")
A31: =IF(TRIM(INDEX(DonGia!$A:$A,33))="","",IF(COUNTIF(INDEX(DonGia!$A:$A,4):INDEX(DonGia!$A:$A,33),INDEX(DonGia!$A:$A,33))=1,MAX($A$1:A30)+1,"")) | B31: =IFERROR(INDEX(DonGia!$A:$A,MATCH(ROW()-1,$A$2:$A$201,0)+3),"") | C31: =IF(TRIM(INDEX(VatLieu!$A:$A,33))="","",IF(COUNTIF(INDEX(VatLieu!$A:$A,4):INDEX(VatLieu!$A:$A,33),INDEX(VatLieu!$A:$A,33))=1,MAX($C$1:C30)+1,"")) | D31: =IFERROR(INDEX(VatLieu!$A:$A,MATCH(ROW()-1,$C$2:$C$201,0)+3),"") | E31: =IF(TRIM(INDEX(CongDoan!$A:$A,33))="","",IF(COUNTIF(INDEX(CongDoan!$A:$A,4):INDEX(CongDoan!$A:$A,33),INDEX(CongDoan!$A:$A,33))=1,MAX($E$1:E30)+1,"")) | F31: =IFERROR(INDEX(CongDoan!$A:$A,MATCH(ROW()-1,$E$2:$E$197,0)+3),"")
A32: =IF(TRIM(INDEX(DonGia!$A:$A,34))="","",IF(COUNTIF(INDEX(DonGia!$A:$A,4):INDEX(DonGia!$A:$A,34),INDEX(DonGia!$A:$A,34))=1,MAX($A$1:A31)+1,"")) | B32: =IFERROR(INDEX(DonGia!$A:$A,MATCH(ROW()-1,$A$2:$A$201,0)+3),"") | C32: =IF(TRIM(INDEX(VatLieu!$A:$A,34))="","",IF(COUNTIF(INDEX(VatLieu!$A:$A,4):INDEX(VatLieu!$A:$A,34),INDEX(VatLieu!$A:$A,34))=1,MAX($C$1:C31)+1,"")) | D32: =IFERROR(INDEX(VatLieu!$A:$A,MATCH(ROW()-1,$C$2:$C$201,0)+3),"") | E32: =IF(TRIM(INDEX(CongDoan!$A:$A,34))="","",IF(COUNTIF(INDEX(CongDoan!$A:$A,4):INDEX(CongDoan!$A:$A,34),INDEX(CongDoan!$A:$A,34))=1,MAX($E$1:E31)+1,"")) | F32: =IFERROR(INDEX(CongDoan!$A:$A,MATCH(ROW()-1,$E$2:$E$197,0)+3),"")
A33: =IF(TRIM(INDEX(DonGia!$A:$A,35))="","",IF(COUNTIF(INDEX(DonGia!$A:$A,4):INDEX(DonGia!$A:$A,35),INDEX(DonGia!$A:$A,35))=1,MAX($A$1:A32)+1,"")) | B33: =IFERROR(INDEX(DonGia!$A:$A,MATCH(ROW()-1,$A$2:$A$201,0)+3),"") | C33: =IF(TRIM(INDEX(VatLieu!$A:$A,35))="","",IF(COUNTIF(INDEX(VatLieu!$A:$A,4):INDEX(VatLieu!$A:$A,35),INDEX(VatLieu!$A:$A,35))=1,MAX($C$1:C32)+1,"")) | D33: =IFERROR(INDEX(VatLieu!$A:$A,MATCH(ROW()-1,$C$2:$C$201,0)+3),"") | E33: =IF(TRIM(INDEX(CongDoan!$A:$A,35))="","",IF(COUNTIF(INDEX(CongDoan!$A:$A,4):INDEX(CongDoan!$A:$A,35),INDEX(CongDoan!$A:$A,35))=1,MAX($E$1:E32)+1,"")) | F33: =IFERROR(INDEX(CongDoan!$A:$A,MATCH(ROW()-1,$E$2:$E$197,0)+3),"")
A34: =IF(TRIM(INDEX(DonGia!$A:$A,36))="","",IF(COUNTIF(INDEX(DonGia!$A:$A,4):INDEX(DonGia!$A:$A,36),INDEX(DonGia!$A:$A,36))=1,MAX($A$1:A33)+1,"")) | B34: =IFERROR(INDEX(DonGia!$A:$A,MATCH(ROW()-1,$A$2:$A$201,0)+3),"") | C34: =IF(TRIM(INDEX(VatLieu!$A:$A,36))="","",IF(COUNTIF(INDEX(VatLieu!$A:$A,4):INDEX(VatLieu!$A:$A,36),INDEX(VatLieu!$A:$A,36))=1,MAX($C$1:C33)+1,"")) | D34: =IFERROR(INDEX(VatLieu!$A:$A,MATCH(ROW()-1,$C$2:$C$201,0)+3),"") | E34: =IF(TRIM(INDEX(CongDoan!$A:$A,36))="","",IF(COUNTIF(INDEX(CongDoan!$A:$A,4):INDEX(CongDoan!$A:$A,36),INDEX(CongDoan!$A:$A,36))=1,MAX($E$1:E33)+1,"")) | F34: =IFERROR(INDEX(CongDoan!$A:$A,MATCH(ROW()-1,$E$2:$E$197,0)+3),"")
A35: =IF(TRIM(INDEX(DonGia!$A:$A,37))="","",IF(COUNTIF(INDEX(DonGia!$A:$A,4):INDEX(DonGia!$A:$A,37),INDEX(DonGia!$A:$A,37))=1,MAX($A$1:A34)+1,"")) | B35: =IFERROR(INDEX(DonGia!$A:$A,MATCH(ROW()-1,$A$2:$A$201,0)+3),"") | C35: =IF(TRIM(INDEX(VatLieu!$A:$A,37))="","",IF(COUNTIF(INDEX(VatLieu!$A:$A,4):INDEX(VatLieu!$A:$A,37),INDEX(VatLieu!$A:$A,37))=1,MAX($C$1:C34)+1,"")) | D35: =IFERROR(INDEX(VatLieu!$A:$A,MATCH(ROW()-1,$C$2:$C$201,0)+3),"") | E35: =IF(TRIM(INDEX(CongDoan!$A:$A,37))="","",IF(COUNTIF(INDEX(CongDoan!$A:$A,4):INDEX(CongDoan!$A:$A,37),INDEX(CongDoan!$A:$A,37))=1,MAX($E$1:E34)+1,"")) | F35: =IFERROR(INDEX(CongDoan!$A:$A,MATCH(ROW()-1,$E$2:$E$197,0)+3),"")
A36: =IF(TRIM(INDEX(DonGia!$A:$A,38))="","",IF(COUNTIF(INDEX(DonGia!$A:$A,4):INDEX(DonGia!$A:$A,38),INDEX(DonGia!$A:$A,38))=1,MAX($A$1:A35)+1,"")) | B36: =IFERROR(INDEX(DonGia!$A:$A,MATCH(ROW()-1,$A$2:$A$201,0)+3),"") | C36: =IF(TRIM(INDEX(VatLieu!$A:$A,38))="","",IF(COUNTIF(INDEX(VatLieu!$A:$A,4):INDEX(VatLieu!$A:$A,38),INDEX(VatLieu!$A:$A,38))=1,MAX($C$1:C35)+1,"")) | D36: =IFERROR(INDEX(VatLieu!$A:$A,MATCH(ROW()-1,$C$2:$C$201,0)+3),"") | E36: =IF(TRIM(INDEX(CongDoan!$A:$A,38))="","",IF(COUNTIF(INDEX(CongDoan!$A:$A,4):INDEX(CongDoan!$A:$A,38),INDEX(CongDoan!$A:$A,38))=1,MAX($E$1:E35)+1,"")) | F36: =IFERROR(INDEX(CongDoan!$A:$A,MATCH(ROW()-1,$E$2:$E$197,0)+3),"")
A37: =IF(TRIM(INDEX(DonGia!$A:$A,39))="","",IF(COUNTIF(INDEX(DonGia!$A:$A,4):INDEX(DonGia!$A:$A,39),INDEX(DonGia!$A:$A,39))=1,MAX($A$1:A36)+1,"")) | B37: =IFERROR(INDEX(DonGia!$A:$A,MATCH(ROW()-1,$A$2:$A$201,0)+3),"") | C37: =IF(TRIM(INDEX(VatLieu!$A:$A,39))="","",IF(COUNTIF(INDEX(VatLieu!$A:$A,4):INDEX(VatLieu!$A:$A,39),INDEX(VatLieu!$A:$A,39))=1,MAX($C$1:C36)+1,"")) | D37: =IFERROR(INDEX(VatLieu!$A:$A,MATCH(ROW()-1,$C$2:$C$201,0)+3),"") | E37: =IF(TRIM(INDEX(CongDoan!$A:$A,39))="","",IF(COUNTIF(INDEX(CongDoan!$A:$A,4):INDEX(CongDoan!$A:$A,39),INDEX(CongDoan!$A:$A,39))=1,MAX($E$1:E36)+1,"")) | F37: =IFERROR(INDEX(CongDoan!$A:$A,MATCH(ROW()-1,$E$2:$E$197,0)+3),"")
A38: =IF(TRIM(INDEX(DonGia!$A:$A,40))="","",IF(COUNTIF(INDEX(DonGia!$A:$A,4):INDEX(DonGia!$A:$A,40),INDEX(DonGia!$A:$A,40))=1,MAX($A$1:A37)+1,"")) | B38: =IFERROR(INDEX(DonGia!$A:$A,MATCH(ROW()-1,$A$2:$A$201,0)+3),"") | C38: =IF(TRIM(INDEX(VatLieu!$A:$A,40))="","",IF(COUNTIF(INDEX(VatLieu!$A:$A,4):INDEX(VatLieu!$A:$A,40),INDEX(VatLieu!$A:$A,40))=1,MAX($C$1:C37)+1,"")) | D38: =IFERROR(INDEX(VatLieu!$A:$A,MATCH(ROW()-1,$C$2:$C$201,0)+3),"") | E38: =IF(TRIM(INDEX(CongDoan!$A:$A,40))="","",IF(COUNTIF(INDEX(CongDoan!$A:$A,4):INDEX(CongDoan!$A:$A,40),INDEX(CongDoan!$A:$A,40))=1,MAX($E$1:E37)+1,"")) | F38: =IFERROR(INDEX(CongDoan!$A:$A,MATCH(ROW()-1,$E$2:$E$197,0)+3),"")
A39: =IF(TRIM(INDEX(DonGia!$A:$A,41))="","",IF(COUNTIF(INDEX(DonGia!$A:$A,4):INDEX(DonGia!$A:$A,41),INDEX(DonGia!$A:$A,41))=1,MAX($A$1:A38)+1,"")) | B39: =IFERROR(INDEX(DonGia!$A:$A,MATCH(ROW()-1,$A$2:$A$201,0)+3),"") | C39: =IF(TRIM(INDEX(VatLieu!$A:$A,41))="","",IF(COUNTIF(INDEX(VatLieu!$A:$A,4):INDEX(VatLieu!$A:$A,41),INDEX(VatLieu!$A:$A,41))=1,MAX($C$1:C38)+1,"")) | D39: =IFERROR(INDEX(VatLieu!$A:$A,MATCH(ROW()-1,$C$2:$C$201,0)+3),"") | E39: =IF(TRIM(INDEX(CongDoan!$A:$A,41))="","",IF(COUNTIF(INDEX(CongDoan!$A:$A,4):INDEX(CongDoan!$A:$A,41),INDEX(CongDoan!$A:$A,41))=1,MAX($E$1:E38)+1,"")) | F39: =IFERROR(INDEX(CongDoan!$A:$A,MATCH(ROW()-1,$E$2:$E$197,0)+3),"")
A40: =IF(TRIM(INDEX(DonGia!$A:$A,42))="","",IF(COUNTIF(INDEX(DonGia!$A:$A,4):INDEX(DonGia!$A:$A,42),INDEX(DonGia!$A:$A,42))=1,MAX($A$1:A39)+1,"")) | B40: =IFERROR(INDEX(DonGia!$A:$A,MATCH(ROW()-1,$A$2:$A$201,0)+3),"") | C40: =IF(TRIM(INDEX(VatLieu!$A:$A,42))="","",IF(COUNTIF(INDEX(VatLieu!$A:$A,4):INDEX(VatLieu!$A:$A,42),INDEX(VatLieu!$A:$A,42))=1,MAX($C$1:C39)+1,"")) | D40: =IFERROR(INDEX(VatLieu!$A:$A,MATCH(ROW()-1,$C$2:$C$201,0)+3),"") | E40: =IF(TRIM(INDEX(CongDoan!$A:$A,42))="","",IF(COUNTIF(INDEX(CongDoan!$A:$A,4):INDEX(CongDoan!$A:$A,42),INDEX(CongDoan!$A:$A,42))=1,MAX($E$1:E39)+1,"")) | F40: =IFERROR(INDEX(CongDoan!$A:$A,MATCH(ROW()-1,$E$2:$E$197,0)+3),"")
...
